Workbook

Sheet scoringR1_base
A1: VARIABLES | B1: REFERENCE | C1: DESCRIPTION | D1: TIMESCALE | E1: RESOLUTION | F1: DOI | G1: SCORING (1-5, 5 being the most important)
H2: XH | I2: KD | J2: DG | K2: SG | L2: CM | M2: VS | N2: CD
A3: PHYSICAL SYSTEM | C3: This system includes variables regarding the physical properties of the environment in the area that is not being influenced by human actions | D3: - | E3: - | G3: - | H3: ='XH1'!G3 -> - | I3: ='KD1'!G3 -> 0 | J3: ='DG1'!G3 -> - | K3: ='SG1'!G3 -> - | L3: ='CM1'!G3 -> - | M3: ='VS1'!G3 -> -
A4: Soil Subsystem | C4: This sub system concentrate on variables that are related to the soil | D4: - | E4: - | G4: - | H4: ='XH1'!G4 -> - | I4: ='KD1'!G4 -> 0 | J4: ='DG1'!G4 -> - | K4: ='SG1'!G4 -> - | L4: ='CM1'!G4 -> - | M4: ='VS1'!G4 -> -
A5: Soil organic carbon (SOC) | B5: Poggio et al. 2021 | C5: SOC shows the amount of soil organic carbon in each area from 0-60cm of depths | D5: 1960-2020 (mean) | E5: 250 m cellsize ~0.25 arcminute | F5: https://files.isric.org/soilgrids/latest/ | G5: =AVERAGE(H5:N5) -> 3.8571429 | H5: ='XH1'!G5 -> 4 | I5: ='KD1'!G5 -> 5 | J5: ='DG1'!G5 -> 3 | K5: ='SG1'!G5 -> 3 | L5: ='CM1'!G5 -> 3 | M5: ='VS1'!G5 -> 5 | N5: ='CD1'!G5 -> 4
A6: Clay-silt content | B6: Poggio et al. 2021 | C6: Clay-silt shows the combined amount of clay and silt in the soil from 0-60cm depths | D6: 1960-2020 (mean) | E6: 250 m cellsize ~0.25 arcminute | F6: https://files.isric.org/soilgrids/latest/ | G6: =AVERAGE(H6:N6) -> 2.5714286 | H6: ='XH1'!G6 -> 3 | I6: ='KD1'!G6 -> 3 | J6: ='DG1'!G6 -> 2 | K6: ='SG1'!G6 -> 2 | L6: ='CM1'!G6 -> 3 | M6: ='VS1'!G6 -> 3 | N6: ='CD1'!G6 -> 2
A7: Soil plant available phosphorous | B7: McDowell et al. 2023 | C7: Amount of phosphorous that is available for plant to absorb from the soil from 0-20cm depth | D7: 2000-2019 (mean) | E7: 0.5 arcminute | F7: https://figshare.com/articles/dataset/Global_Available_Soil_Phosphorus_Database/14241854 | G7: =AVERAGE(H7:N7) -> 3.4285714 | H7: ='XH1'!G7 -> 4 | I7: ='KD1'!G7 -> 3 | J7: ='DG1'!G7 -> 4 | K7: ='SG1'!G7 -> 3 | L7: ='CM1'!G7 -> 4 | M7: ='VS1'!G7 -> 3 | N7: ='CD1'!G7 -> 3
A8: Evapotranspiration | B8: Zhang et al. 2024 | C8: This shows the amount of evapotranspiration in the area | D8: 1982-2020 | E8: 6 arcminutes | F8: Zhang, K., Chen, H., Ma, N. et al. A global dataset of terrestrial evapotranspiration and soil moisture dynamics from 1982 to 2020. Sci Data 11, 445 (2024). https://doi.org/10.1038/s41597-024-03271-7 | G8: =AVERAGE(H8:N8) -> 4.4285714 | H8: ='XH1'!G8 -> 5 | I8: ='KD1'!G8 -> 5 | J8: ='DG1'!G8 -> 3 | K8: ='SG1'!G8 -> 5 | L8: ='CM1'!G8 -> 5 | M8: ='VS1'!G8 -> 4 | N8: ='CD1'!G8 -> 4
A9: Soil Moisture | B9: Zhang et al. 2024 | C9: Amount of soil moisture throughout the layers along the vertical root distribution | D9: 1982-2020 | E9: 6 arcminutes | F9: Zhang, K., Chen, H., Ma, N. et al. A global dataset of terrestrial evapotranspiration and soil moisture dynamics from 1982 to 2020. Sci Data 11, 445 (2024). https://doi.org/10.1038/s41597-024-03271-7 | G9: =AVERAGE(H9:N9) -> 4.7142857 | H9: ='XH1'!G9 -> 5 | I9: ='KD1'!G9 -> 5 | J9: ='DG1'!G9 -> 5 | K9: ='SG1'!G9 -> 4 | L9: ='CM1'!G9 -> 5 | M9: ='VS1'!G9 -> 4 | N9: ='CD1'!G9 -> 5
A10: Other variables? | H10: ='XH1'!G10 -> x | I10: ='KD1'!G10 -> 0 | J10: ='DG1'!G10 -> x | K10: ='SG1'!G10 -> x | L10: ='CM1'!G10 -> x | M10: ='VS1'!G10 -> x
A11: Climate Subsystem | C11: This subsystem focus on the climatic variables | D11: - | E11: - | H11: ='XH1'!G11 -> - | I11: ='KD1'!G11 -> 0 | J11: ='DG1'!G11 -> - | K11: ='SG1'!G11 -> - | L11: ='CM1'!G11 -> - | M11: ='VS1'!G11 -> -
A12: Aridity index | B12: Lu et al. 2025 | C12: Aridity index is used to determine the aridity in the area by looking at, for example, precipitation or evapotranspiration values | D12: 2003-2022 | E12: 3 arcminute | F12: Lu, J., Yao, L., Qin, J., Jiang, H., & Zhou, C. (2025). Global reconstruction of gridded aridity index and its spatial and temporal characterization from 2003 to 2022. International Journal of Digital Earth, 18(1). https://doi.org/10.1080/17538947.2025.2473639 | G12: =AVERAGE(H12:N12) -> 4.1428571 | H12: ='XH1'!G12 -> 5 | I12: ='KD1'!G12 -> 5 | J12: ='DG1'!G12 -> 3 | K12: ='SG1'!G12 -> 4 | L12: ='CM1'!G12 -> 3 | M12: ='VS1'!G12 -> 4 | N12: ='CD1'!G12 -> 5
A13: Precipitation (MSWEP) | B13: Beck et al. 2019 | C13: MSWEP shows the 3 hourly precipitation data from 1979 to 2017 | D13: 1979-2017 (annual mean) | E13: 6 arcminute | F13: Beck, H. E., E. F. Wood, M. Pan, C. K. Fisher, D. G. Miralles, A. I. J. M. van Dijk, T. R. McVicar, and R. F. Adler, 2019: MSWEP V2 Global 3-Hourly 0.1° Precipitation: Methodology and Quantitative Assessment. Bull. Amer. Meteor. Soc., 100, 473–500, https://doi.org/10.1175/BAMS-D-17-0138.1 | G13: =AVERAGE(H13:N13) -> 4.4285714 | H13: ='XH1'!G13 -> 4 | I13: ='KD1'!G13 -> 5 | J13: ='DG1'!G13 -> 5 | K13: ='SG1'!G13 -> 3 | L13: ='CM1'!G13 -> 5 | M13: ='VS1'!G13 -> 5 | N13: ='CD1'!G13 -> 4
A14: Growing degree days | B14: Beck et al. 2022 | C14: This measure the accumulated heat above certain base temperature which can estimate the growth and development of plants and insects | D14: 1979-2025 | E14: 6 arcminute | F14: Beck, H.E. et al. (2022) ‘MSWX: Global 3-Hourly 0.1° Bias-Corrected Meteorological Data Including Near-Real-Time Updates and Forecast Ensembles’. Available at: https://doi.org/10.1175/BAMS-D-21-0145.1. | G14: =AVERAGE(H14:N14) -> 4.4285714 | H14: ='XH1'!G14 -> 5 | I14: ='KD1'!G14 -> 5 | J14: ='DG1'!G14 -> 4 | K14: ='SG1'!G14 -> 4 | L14: ='CM1'!G14 -> 5 | M14: ='VS1'!G14 -> 4 | N14: ='CD1'!G14 -> 4
A15: Drought index (SPEI) | B15: Solomon et al. 2023 | C15: Drought index (SPEI) was calculated from two precipitation and two evapotranspiration datasets | D15: 1981-2022 | E15: 5km gridded ~2.5 arcminute | F15: Gebrechorkos, S. H., Peng, J., Dyer, E., Miralles, D. G., Vicente-Serrano, S. M., Funk, C., Beck, H. E., Asfaw, D. T., Singer, M. B., and Dadson, S. J.: Global high-resolution drought indices for 1981–2022, Earth Syst. Sci. Data, 15, 5449–5466, https://doi.org/10.5194/essd-15-5449-2023 | G15: =AVERAGE(H15:N15) -> 3.4285714 | H15: ='XH1'!G15 -> 4 | I15: ='KD1'!G15 -> 3 | J15: ='DG1'!G15 -> 4 | K15: ='SG1'!G15 -> 3 | L15: ='CM1'!G15 -> 3 | M15: ='VS1'!G15 -> 3 | N15: ='CD1'!G15 -> 4
A16: Warm spell duration index (WSDI) | B16: Beck et al. 2022 | C16: This indicator shows the amount of conscutive days that the temperature is high (drought). | D16: 1979-2025 | E16: 6 arcminute | F16: Beck, H.E. et al. (2022) ‘MSWX: Global 3-Hourly 0.1° Bias-Corrected Meteorological Data Including Near-Real-Time Updates and Forecast Ensembles’. Available at: https://doi.org/10.1175/BAMS-D-21-0145.1. | G16: =AVERAGE(H16:N16) -> 2.7142857 | H16: ='XH1'!G16 -> 4 | I16: ='KD1'!G16 -> 2 | J16: ='DG1'!G16 -> 4 | K16: ='SG1'!G16 -> 1 | L16: ='CM1'!G16 -> 3 | M16: ='VS1'!G16 -> 2 | N16: ='CD1'!G16 -> 3
A17: Other variables? | H17: ='XH1'!G17 -> x | I17: ='KD1'!G17 -> Renewable water availability | J17: ='DG1'!G17 -> x | K17: ='SG1'!G17 -> x | L17: ='CM1'!G17 -> x | M17: ='VS1'!G17 -> x
A18: Crop-field Subsystem | C18: Crop-field system is currently considered to be between the two main systems (Physical and Human). This system focuses on the variables that are related to crop species | D18: - | E18: - | H18: ='XH1'!G18 -> - | I18: ='KD1'!G18 -> 0 | J18: ='DG1'!G18 -> - | K18: ='SG1'!G18 -> - | L18: ='CM1'!G18 -> - | M18: ='VS1'!G18 -> -
A19: Diversity of crops | B19: Sara Heikonen / Heikonen et al. 2025 | C19: Diversity of crops (30 major food crop types based on SPAM crops) | D19: 1990-2020 | E19: 5 arcminute | F19: https://mapspam.info/data/ | G19: =AVERAGE(H19:N19) -> 3.4285714 | H19: ='XH1'!G19 -> 5 | I19: ='KD1'!G19 -> 5 | J19: ='DG1'!G19 -> 3 | K19: ='SG1'!G19 -> 4 | L19: ='CM1'!G19 -> 2 | M19: ='VS1'!G19 -> 3 | N19: ='CD1'!G19 -> 2
A20: Fraction of cropland per total land area | B20: Matej et al. 2025 | C20: This variable captures the intensity of the cropland in each area by calculating the fraction of actual cropland in the cropland area | D20: 1992-2020 | E20: 0.5 arcminute | F20: https://mapspam.info/data/ | G20: =AVERAGE(H20:N20) -> 3 | H20: ='XH1'!G20 -> 4 | I20: ='KD1'!G20 -> 5 | J20: ='DG1'!G20 -> 2 | K20: ='SG1'!G20 -> 4 | L20: ='CM1'!G20 -> 1 | M20: ='VS1'!G20 -> 2 | N20: ='CD1'!G20 -> 3
A21: Kilo-calories produced from crops (from SPAM) | B21: SPAM 2000, SPAM 2005, SPAM 2010, SPAM 2020 | C21: Shows the amount of kilo-calories being produced from SPAM crops classes | D21: 2000-2020 | E21: 5 arcminute | F21: https://mapspam.info/data/ | G21: =AVERAGE(H21:N21) -> 3.1428571 | H21: ='XH1'!G21 -> 5 | I21: ='KD1'!G21 -> 2 | J21: ='DG1'!G21 -> 4 | K21: ='SG1'!G21 -> 4 | L21: ='CM1'!G21 -> 1 | M21: ='VS1'!G21 -> 3 | N21: ='CD1'!G21 -> 3
A22: Harvested crop products (HANPP) | B22: Matej et al. 2025 | C22: Shows the amount of mass of carbon being harvested from 22 crop classes | D22: 1992-2020 | E22: 0.5 arcminute | F22: Matej, S., Weidinger, F., Kaufmann, L. et al. A global land-use data cube 1992–2020 based on the Human Appropriation of Net Primary Production. Sci Data 12, 511 (2025). https://doi.org/10.1038/s41597-025-04788-1 | G22: =AVERAGE(H22:N22) -> 3.5714286 | H22: ='XH1'!G22 -> 5 | I22: ='KD1'!G22 -> 2 | J22: ='DG1'!G22 -> 4 | K22: ='SG1'!G22 -> 5 | L22: ='CM1'!G22 -> 1 | M22: ='VS1'!G22 -> 4 | N22: ='CD1'!G22 -> 4
A23: Potential Net primary production (NPP Pot) | B23: Matej et al. 2025 | C23: Potential biomass that is available in each area from agriculture and forestry. | D23: 1992-2020 | E23: 0.5 arcminute | F23: Matej, S., Weidinger, F., Kaufmann, L. et al. A global land-use data cube 1992–2020 based on the Human Appropriation of Net Primary Production. Sci Data 12, 511 (2025). https://doi.org/10.1038/s41597-025-04788-1 | G23: =AVERAGE(H23:N23) -> 3.3333333 | H23: ='XH1'!G23 -> 4 | I23: ='KD1'!G23 -> 3 | J23: ='DG1'!G23 -> 3 | K23: ='SG1'!G23 -> x | L23: ='CM1'!G23 -> 1 | M23: ='VS1'!G23 -> 5 | N23: ='CD1'!G23 -> 4
A24: Greenhouse gas emissions from cropland | B24: Cao et al. 2025 (Preprint) | C24: Emission of carbon dioxide, methane, and nitrous oxide from 46 crops circa 2020 | D24: 2020 | E24: 5 arcminute | F24: https://doi.org/10.21203/rs.3.rs-6622054/v1 | G24: =AVERAGE(H24:N24) -> 3.0714286 | H24: 2.5 | I24: ='KD1'!G24 -> 5 | J24: ='DG1'!G24 -> 4 | K24: ='SG1'!G24 -> 3 | L24: ='CM1'!G24 -> 1 | M24: ='VS1'!G24 -> 2 | N24: ='CD1'!G24 -> 4
A25: Other variables? | H25: ='XH1'!G25 -> 0 | I25: ='KD1'!G25 -> Crop-specific yield (irrig./rainfed); crop-specific harvested area (irrig./rainfed) | J25: ='DG1'!G25 -> 0 | K25: ='SG1'!G25 -> 0 | L25: ='CM1'!G25 -> 0 | M25: ='VS1'!G25 -> 0 | N25: ='CD1'!G25 -> 0
H26: ='XH1'!G26 -> - | I26: ='KD1'!G26 -> 0 | J26: ='DG1'!G26 -> - | K26: ='SG1'!G26 -> - | L26: ='CM1'!G26 -> - | M26: ='VS1'!G26 -> -
A27: HUMAN SYSTEM | C27: Human system includes the effect from human towards the crop production system including practices that human has used to influence the crop production as well as the socio-economic variables that affect agriculture workers or policies | D27: - | E27: - | H27: ='XH1'!G27 -> - | I27: ='KD1'!G27 -> 0 | J27: ='DG1'!G27 -> - | K27: ='SG1'!G27 -> - | L27: ='CM1'!G27 -> - | M27: ='VS1'!G27 -> -
A28: Management Subsystem | C28: This subsystem includes variables that is related to management | D28: - | E28: - | H28: ='XH1'!G28 -> - | I28: ='KD1'!G28 -> 0 | J28: ='DG1'!G28 -> - | K28: ='SG1'!G28 -> - | L28: ='CM1'!G28 -> - | M28: ='VS1'!G28 -> -
A29: Field size | B29: Lesiv et al. 2019 | C29: Field size shows the categorial data of field size from 1-5 | D29: 2017 | E29: ~0.3 arcminute | F29: https://pure.iiasa.ac.at/id/eprint/15526/ | G29: =MEDIAN(H29:N29) -> 4 | H29: ='XH1'!G29 -> 4 | I29: ='KD1'!G29 -> 4 | J29: ='DG1'!G29 -> 3 | K29: ='SG1'!G29 -> 4 | L29: ='CM1'!G29 -> 1 | M29: ='VS1'!G29 -> 5 | N29: ='CD1'!G29 -> 0
A30: Pesticide application rate | B30: Maggi et al. 2019 | C30: Application rate of pesticide per each crop | D30: 2015-2025 | E30: 5 arcminute | F30: https://figshare.com/articles/dataset/PEST-CHEMGRIDS_v1/7764014/5 | G30: =AVERAGE(H30:N30) -> 3.8571429 | H30: ='XH1'!G30 -> 3 | I30: ='KD1'!G30 -> 4 | J30: ='DG1'!G30 -> 4 | K30: ='SG1'!G30 -> 5 | L30: ='CM1'!G30 -> 4 | M30: ='VS1'!G30 -> 4 | N30: ='CD1'!G30 -> 3
A31: N fertilizer application rate | B31: Adalibieke et al. 2023 | C31: This shows the N fertilizer application rate for each crop | D31: 1961-2020 | E31: 5 arcminute | F31: https://data.tpdc.ac.cn/en/data/1e31ad1f-5904-4b49-8796-b379c37e7dba | G31: =AVERAGE(H31:N31) -> 4.5714286 | H31: ='XH1'!G31 -> 5 | I31: ='KD1'!G31 -> 5 | J31: ='DG1'!G31 -> 4 | K31: ='SG1'!G31 -> 5 | L31: ='CM1'!G31 -> 5 | M31: ='VS1'!G31 -> 4 | N31: ='CD1'!G31 -> 4
A32: Fraction of irrigated cropland | B32: Kebede et al. 2025 | C32: Fraction of irrigated cropland with the total cropland area in each grid | D32: 2000-2015 | E32: 5 arcminute | F32: https://doi.org/10.1038/s41597-024-04313-w | G32: =AVERAGE(H32:N32) -> 4.2857143 | H32: ='XH1'!G32 -> 5 | I32: ='KD1'!G32 -> 5 | J32: ='DG1'!G32 -> 4 | K32: ='SG1'!G32 -> 5 | L32: ='CM1'!G32 -> 3 | M32: ='VS1'!G32 -> 4 | N32: ='CD1'!G32 -> 4
A33: Machinery | B33: USDA 2023 | C33: Amount of machinery used in 1000 horsepower (CV) in metric unit per 100 hectares of cropland in each country | D33: 1961-2020 | E33: Country | F33: October 2024 update has remove the data | G33: =AVERAGE(H33:N33) -> 3.7142857 | H33: ='XH1'!G33 -> 4 | I33: ='KD1'!G33 -> 5 | J33: ='DG1'!G33 -> 2 | K33: ='SG1'!G33 -> 5 | L33: ='CM1'!G33 -> 4 | M33: ='VS1'!G33 -> 3 | N33: ='CD1'!G33 -> 3
A34: Agricultural workers | B34: FAO 2023 | C34: Number of agricultural workers in each country | D34: 1991-2020 | E34: Country | F34: https://www.fao.org/faostat/en/#data/OEA | G34: =AVERAGE(H34:N34) -> 3.4285714 | H34: ='XH1'!G34 -> 4 | I34: ='KD1'!G34 -> 5 | J34: ='DG1'!G34 -> 3 | K34: ='SG1'!G34 -> 4 | L34: ='CM1'!G34 -> 2 | M34: ='VS1'!G34 -> 3 | N34: ='CD1'!G34 -> 3
A35: Human pressure (NPP Act / NPP Pot) | B35: Matej et al. 2025 | C35: This shows the human influence on the biomass in Net Primary Production (NPP) in the ecosystem through land use by dividing NPP actual with NPP potential | D35: 1992-2020 | E35: 0.5 arcminute | F35: Matej, S., Weidinger, F., Kaufmann, L. et al. A global land-use data cube 1992–2020 based on the Human Appropriation of Net Primary Production. Sci Data 12, 511 (2025). https://doi.org/10.1038/s41597-025-04788-1 | G35: =AVERAGE(H35:N35) -> 2.5 | H35: ='XH1'!G35 -> 4 | I35: ='KD1'!G35 -> 3 | J35: ='DG1'!G35 -> 2 | K35: ='SG1'!G35 -> 3 | L35: ='CM1'!G35 -> 1 | M35: ='VS1'!G35 -> 2 | N35: x
A36: Other variables? | H36: ='XH1'!G36 -> x | I36: ='KD1'!G36 -> Blue and green crop water requirements | J36: ='DG1'!G36 -> x | K36: ='SG1'!G36 -> x | L36: ='CM1'!G36 -> x | M36: ='VS1'!G36 -> x
A37: Socio-economic Subsytem | C37: This subsystem consisted of socio-economic variables | D37: - | E37: - | H37: ='XH1'!G37 -> - | I37: ='KD1'!G37 -> 0 | J37: ='DG1'!G37 -> - | K37: ='SG1'!G37 -> - | L37: ='CM1'!G37 -> - | M37: ='VS1'!G37 -> -
A38: GNI | B38: Matti Kummu | C38: Gross National Income shows the values of national income for each country | D38: 1990-2021 | E38: admin 2 | G38: =AVERAGE(H38:N38) -> 2.6666667 | H38: ='XH1'!G38 -> 3 | I38: ='KD1'!G38 -> 3 | J38: ='DG1'!G38 -> 4 | K38: ='SG1'!G38 -> 3 | L38: ='CM1'!G38 -> 1 | M38: ='VS1'!G38 -> 2 | N38: x
A39: Years of schooling | B39: Matti Kummu | C39: This shows the amount of average years of schooling in the population | D39: 1990-2021 | E39: admin 1 | G39: =AVERAGE(H39:N39) -> 2.6666667 | H39: ='XH1'!G39 -> 3 | I39: ='KD1'!G39 -> 5 | J39: ='DG1'!G39 -> 3 | K39: ='SG1'!G39 -> 2 | L39: ='CM1'!G39 -> 1 | M39: ='VS1'!G39 -> 2 | N39: x
A40: Governance index | B40: Matti Kummu | C40: Governance inis based on World Bank Group (Worldwide Governance Indicators) which shows how good is the governance | D40: 1990-2021 | E40: admin 0 | G40: =AVERAGE(H40:N40) -> 2.5 | H40: ='XH1'!G40 -> 3 | I40: ='KD1'!G40 -> 3 | J40: ='DG1'!G40 -> 4 | K40: ='SG1'!G40 -> 1 | L40: ='CM1'!G40 -> 1 | M40: ='VS1'!G40 -> 3 | N40: x
...

Sheet variables_round1
A1: Round1 - Chosen varaibles
A2: VARIABLES | B2: REFERENCE | C2: DESCRIPTION | D2: TIMESCALE | E2: RESOLUTION | F2: DOI | G2: SCORING (1-5, 5 being the most important)
A3: Soil SubSystem
A4: Soil organic carbon (SOC) | B4: Poggio et al. 2021 | C4: SOC shows the amount of soil organic carbon in each area from 0-60cm of depths | D4: 1960-2020 (mean) | E4: 250 m cellsize ~0.25 arcminute | F4: https://files.isric.org/soilgrids/latest/ | G4: 3.8333333 | H4: 4 | I4: 5 | J4: 3 | K4: 3 | L4: 3 | M4: 5
A5: Soil plant available phosphorous | B5: McDowell et al. 2023 | C5: Amount of phosphorous that is available for plant to absorb from the soil from 0-20cm depth | D5: 2000-2019 (mean) | E5: 0.5 arcminute | F5: https://figshare.com/articles/dataset/Global_Available_Soil_Phosphorus_Database/14241854 | G5: 3.5 | H5: 4 | I5: 3 | J5: 4 | K5: 3 | L5: 4 | M5: 3
A6: Evapotranspiration (Ashwath) - GLEAM | B6: Zhang et al. 2024 | C6: This shows the amount of evapotranspiration in the area | D6: 1982-2020 | E6: 6 arcminutes | F6: Zhang, K., Chen, H., Ma, N. et al. A global dataset of terrestrial evapotranspiration and soil moisture dynamics from 1982 to 2020. Sci Data 11, 445 (2024). https://doi.org/10.1038/s41597-024-03271-7 | G6: 4.5 | H6: 5 | I6: 5 | J6: 3 | K6: 5 | L6: 5 | M6: 4
A7: Soil Moisture (Ashwath) -> Available on Puhti - GLEAM / NCAR / ISMN | B7: Zhang et al. 2024 | C7: Amount of soil moisture throughout the layers along the vertical root distribution | D7: 1982-2020 | E7: 6 arcminutes | F7: Zhang, K., Chen, H., Ma, N. et al. A global dataset of terrestrial evapotranspiration and soil moisture dynamics from 1982 to 2020. Sci Data 11, 445 (2024). https://doi.org/10.1038/s41597-024-03271-7 | G7: 4.6666667 | H7: 5 | I7: 5 | J7: 5 | K7: 4 | L7: 5 | M7: 4
A9: Climate SubSystem
A10: Aridity index (Create) | B10: Lu et al. 2025 | C10: Aridity index is used to determine the aridity in the area by looking at, for example, precipitation or evapotranspiration values | D10: 2003-2022 | E10: 3 arcminute | F10: Lu, J., Yao, L., Qin, J., Jiang, H., & Zhou, C. (2025). Global reconstruction of gridded aridity index and its spatial and temporal characterization from 2003 to 2022. International Journal of Digital Earth, 18(1). https://doi.org/10.1080/17538947.2025.2473639 | G10: 4 | H10: 5 | I10: 5 | J10: 3 | K10: 4 | L10: 3 | M10: 4
A11: Precipitation (MSWEP) | B11: Beck et al. 2019 | C11: MSWEP shows the 3 hourly precipitation data from 1979 to 2017 | D11: 1979-2017 (annual mean) | E11: 6 arcminute | F11: Beck, H. E., E. F. Wood, M. Pan, C. K. Fisher, D. G. Miralles, A. I. J. M. van Dijk, T. R. McVicar, and R. F. Adler, 2019: MSWEP V2 Global 3-Hourly 0.1° Precipitation: Methodology and Quantitative Assessment. Bull. Amer. Meteor. Soc., 100, 473–500, https://doi.org/10.1175/BAMS-D-17-0138.1 | G11: 4.5 | H11: 4 | I11: 5 | J11: 5 | K11: 3 | L11: 5 | M11: 5
A12: Growing degree days (Create) | B12: Beck et al. 2022 | C12: This measure the accumulated heat above certain base temperature which can estimate the growth and development of plants and insects | D12: 1979-2025 | E12: 6 arcminute | F12: Beck, H.E. et al. (2022) ‘MSWX: Global 3-Hourly 0.1° Bias-Corrected Meteorological Data Including Near-Real-Time Updates and Forecast Ensembles’. Available at: https://doi.org/10.1175/BAMS-D-21-0145.1. | G12: 4.5 | H12: 5 | I12: 5 | J12: 4 | K12: 4 | L12: 5 | M12: 4
A14: Crop-field SubSystem
A15: Diversity of crops | B15: Sara Heikonen / Heikonen et al. 2025 | C15: Diversity of crops (30 major food crop types based on SPAM crops) | D15: 1990-2020 | E15: 5 arcminute | F15: https://mapspam.info/data/ | G15: 3.6666667 | H15: 5 | I15: 5 | J15: 3 | K15: 4 | L15: 2 | M15: 3
A16: Harvested crop products (HANPPharv) - Puhti | B16: Matej et al. 2025 | C16: Shows the amount of mass of carbon being harvested from 22 crop classes | D16: 1992-2020 | E16: 0.5 arcminute | F16: Matej, S., Weidinger, F., Kaufmann, L. et al. A global land-use data cube 1992–2020 based on the Human Appropriation of Net Primary Production. Sci Data 12, 511 (2025). https://doi.org/10.1038/s41597-025-04788-1 | G16: 3.5 | H16: 5 | I16: 2 | J16: 4 | K16: 5 | L16: 1 | M16: 4
A18: Management SubSystem
A19: Field size - Also okay if use for one year | B19: Lesiv et al. 2019 | C19: Field size shows the categorial data of field size from 1-5 | D19: 2017 | E19: ~0.3 arcminute | F19: https://pure.iiasa.ac.at/id/eprint/15526/ | G19: 3.5 | H19: 4 | I19: 4 | J19: 3 | K19: 4 | L19: 1 | M19: 5
A20: Pesticide application rate | B20: Maggi et al. 2019 | C20: Application rate of pesticide per each crop | D20: 2015-2025 | E20: 5 arcminute | F20: https://figshare.com/articles/dataset/PEST-CHEMGRIDS_v1/7764014/5 | G20: 4 | H20: 3 | I20: 4 | J20: 4 | K20: 5 | L20: 4 | M20: 4
A21: N fertilizer application rate | B21: Adalibieke et al. 2023 | C21: This shows the N fertilizer application rate for each crop | D21: 1961-2020 | E21: 5 arcminute | F21: https://data.tpdc.ac.cn/en/data/1e31ad1f-5904-4b49-8796-b379c37e7dba | G21: 4.6666667 | H21: 5 | I21: 5 | J21: 4 | K21: 5 | L21: 5 | M21: 4
A22: Fraction of irrigated cropland | B22: Kebede et al. 2025 | C22: Fraction of irrigated cropland with the total cropland area in each grid | D22: 2000-2015 | E22: 5 arcminute | F22: https://doi.org/10.1038/s41597-024-04313-w | G22: 4.3333333 | H22: 5 | I22: 5 | J22: 4 | K22: 5 | L22: 3 | M22: 4
A23: Machinery | B23: USDA 2023 | C23: Amount of machinery used in 1000 horsepower (CV) in metric unit per 100 hectares of cropland in each country | D23: 1961-2020 | E23: Country | F23: October 2024 update has remove the data | G23: 3.8333333 | H23: 4 | I23: 5 | J23: 2 | K23: 5 | L23: 4 | M23: 3
A24: Agricultural workers | B24: FAO 2023 | C24: Number of agricultural workers in each country | D24: 1991-2020 | E24: Country | F24: https://www.fao.org/faostat/en/#data/OEA | G24: 3.5 | H24: 4 | I24: 5 | J24: 3 | K24: 4 | L24: 2 | M24: 3
A26: Recommended variables
A27: Soil pH | B27: YES
A28: Frost days | B28: YES
A29: Surface vs Groundwater sourced irrigation water | B29: FAO / master's thesis
A30: Renewable water availability -> Total renewable water resources | B30: AQUASTAT | C30: country-level data | D30: 1964-2022 | E30: https://data.apps.fao.org/aquastat/?lang=en
A31: Crop-specific yield (irrig./rainfed); crop-specific harvested area (irrig./rainfed) | B31: SPAM possibly | C31: until 2010, maybe 2020 would be better
A32: Blue and green crop water requirements | B32: WATNEEDS
A33: Potential Evaporation -GLEAM | B33: Ashwath
A34: Dominant crops | B34: Need to create -> e.g. PCAM (30arcminute/1961-2014) | C34: The most grown crop (categorial data)
A35: Number of livestocks per unit cropland | B35: Should be able to do it | C35: Grazing land vs. Crop land (GL/CL) | D35: HYDE, HANPP
A36: Trees on cropland | B36: MOD44B.061 Terra Vegetation Continuous Fields | C36: 250m | D36: 2000-2024
A37: Share of productions going for exports | B37: FAOSTAT
A38: Soil plant available nitrogen | B38: Soil grid | C38: country-level data | D38: 1961-2023
A39: Precipitation (wettest 3 consecutive months) | B39: Probably yes | C39: Bio climate variables -> Ask Ashwath
A40: Frequency of droughts during growing season | B40: Ashwath | C40: For this variable I would need to look at the growing season of each crop individually and then assess it
A41: Frequency of dry spells during growing season | B41: Ashwath | C41: Look into growing degree days and which seasons are you looking into. Also, which crop calendar
A42: P fertilizer application | B42: Google this (US researcher Muller something something)
A43: Amounts of irrigation water used
A44: Amounts of actual crops being irrigated
...

Sheet variables_round2
A1: VARIABLES | B1: REFERENCE | C1: DESCRIPTION | D1: TIMESCALE | E1: RESOLUTION | F1: DOI | G1: SCORING (1-5, 5 being the most important)
I2: XH | J2: KD | K2: DG | L2: SG | M2: CM | N2: VS | O2: CD
A3: PHYSICAL SYSTEM | C3: This system includes variables regarding the physical properties of the environment in the area that is not being influenced by human actions | D3: - | E3: - | G3: - | I3: ='XH1'!G3 -> - | J3: ='KD1'!G3 -> 0 | K3: ='DG1'!G3 -> - | L3: ='SG1'!G3 -> - | M3: ='CM1'!G3 -> - | N3: ='VS1'!G3 -> -
A4: Soil Subsystem | C4: This sub system concentrate on variables that are related to the soil | D4: - | E4: - | G4: Mean | H4: Median | I4: ='XH1'!G4 -> - | J4: ='KD1'!G4 -> 0 | K4: ='DG1'!G4 -> - | L4: ='SG1'!G4 -> - | M4: ='CM1'!G4 -> - | N4: ='VS1'!G4 -> -
A5: Soil organic carbon (SOC) | B5: Poggio et al. 2021 | C5: SOC shows the amount of soil organic carbon in each area | D5: 1960-2020 (mean) | E5: 250 m cellsize ~0.25 arcminute | F5: https://files.isric.org/soilgrids/latest/ | G5: =AVERAGE(I5:O5) -> 3.8571429 | H5: =MEDIAN(I5:O5) -> 4 | I5: ='XH1'!G5 -> 4 | J5: ='KD1'!G5 -> 5 | K5: ='DG1'!G5 -> 3 | L5: ='SG1'!G5 -> 3 | M5: ='CM1'!G5 -> 3 | N5: ='VS1'!G5 -> 5 | O5: ='CD1'!G5 -> 4
A6: Clay-silt content | B6: Poggio et al. 2021 | C6: Clay-silt shows the combined amount of clay and silt in the soil | D6: 1960-2020 (mean) | E6: 250 m cellsize ~0.25 arcminute | F6: https://files.isric.org/soilgrids/latest/ | G6: =AVERAGE(I6:O6) -> 2.5714286 | H6: =MEDIAN(I6:O6) -> 3 | I6: ='XH1'!G6 -> 3 | J6: ='KD1'!G6 -> 3 | K6: ='DG1'!G6 -> 2 | L6: ='SG1'!G6 -> 2 | M6: ='CM1'!G6 -> 3 | N6: ='VS1'!G6 -> 3 | O6: ='CD1'!G6 -> 2
A7: Soil plant available phosphorous | B7: McDowell et al. 2023 | C7: Amount of phosphorous that is available for plant to absorb from the soil | D7: 2000-2019 (mean) | E7: 0.5 arcminute | F7: https://figshare.com/articles/dataset/Global_Available_Soil_Phosphorus_Database/14241854 | G7: =AVERAGE(I7:O7) -> 3.4285714 | H7: =MEDIAN(I7:O7) -> 3 | I7: ='XH1'!G7 -> 4 | J7: ='KD1'!G7 -> 3 | K7: ='DG1'!G7 -> 4 | L7: ='SG1'!G7 -> 3 | M7: ='CM1'!G7 -> 4 | N7: ='VS1'!G7 -> 3 | O7: ='CD1'!G7 -> 3
A8: Soil Moisture | B8: Zhang et al. 2024 | C8: Amount of soil moisture throughout the layers along the vertical root distribution | D8: 1982-2020 | E8: 6 arcminutes | F8: Zhang, K., Chen, H., Ma, N. et al. A global dataset of terrestrial evapotranspiration and soil moisture dynamics from 1982 to 2020. Sci Data 11, 445 (2024). https://doi.org/10.1038/s41597-024-03271-7 | G8: =AVERAGE(I8:O8) -> 4.7142857 | H8: =MEDIAN(I8:O8) -> 5 | I8: ='XH1'!G9 -> 5 | J8: ='KD1'!G9 -> 5 | K8: ='DG1'!G9 -> 5 | L8: ='SG1'!G9 -> 4 | M8: ='CM1'!G9 -> 5 | N8: ='VS1'!G9 -> 4 | O8: ='CD1'!G9 -> 5
A9: Add -> Soil pH (SoilGrid) | B9: Poggio et al. 2021 | C9: Amount of pH values in soil | D9: 1960-2020 (mean) | E9: 250 m cellsize ~0.25 arcminute | F9: https://files.isric.org/soilgrids/latest/
A10: Add -> Soil plant available nitrogen | B10: TBD | C10: Amount of nitrogen that is available for plant to absorb from the soil | D10: TBD | E10: TBD | F10: TBD
I13: ='XH1'!G10 -> x | J13: ='KD1'!G10 -> 0 | K13: ='DG1'!G10 -> x | L13: ='SG1'!G10 -> x | M13: ='CM1'!G10 -> x | N13: ='VS1'!G10 -> x
A14: Climate Subsystem | C14: This subsystem focus on the climatic variables | D14: - | E14: - | I14: ='XH1'!G11 -> - | J14: ='KD1'!G11 -> 0 | K14: ='DG1'!G11 -> - | L14: ='SG1'!G11 -> - | M14: ='CM1'!G11 -> - | N14: ='VS1'!G11 -> -
A15: Aridity index* | B15: Lu et al. 2025 | C15: Aridity index is used to determine the aridity in the area by looking at, for example, precipitation or evapotranspiration values | D15: 2003-2022 | E15: 3 arcminute | F15: Lu, J., Yao, L., Qin, J., Jiang, H., & Zhou, C. (2025). Global reconstruction of gridded aridity index and its spatial and temporal characterization from 2003 to 2022. International Journal of Digital Earth, 18(1). https://doi.org/10.1080/17538947.2025.2473639 | G15: =AVERAGE(I15:O15) -> 4.1428571 | H15: =MEDIAN(I15:O15) -> 4 | I15: ='XH1'!G12 -> 5 | J15: ='KD1'!G12 -> 5 | K15: ='DG1'!G12 -> 3 | L15: ='SG1'!G12 -> 4 | M15: ='CM1'!G12 -> 3 | N15: ='VS1'!G12 -> 4 | O15: ='CD1'!G12 -> 5
A16: Precipitation (MSWEP) | B16: Beck et al. 2019 | C16: MSWEP shows the 3 hourly precipitation data from 1979 to 2017 | D16: 1979-2017 (annual mean) | E16: 6 arcminute | F16: Beck, H. E., E. F. Wood, M. Pan, C. K. Fisher, D. G. Miralles, A. I. J. M. van Dijk, T. R. McVicar, and R. F. Adler, 2019: MSWEP V2 Global 3-Hourly 0.1° Precipitation: Methodology and Quantitative Assessment. Bull. Amer. Meteor. Soc., 100, 473–500, https://doi.org/10.1175/BAMS-D-17-0138.1 | G16: =AVERAGE(I16:O16) -> 4.4285714 | H16: =MEDIAN(I16:O16) -> 5 | I16: ='XH1'!G13 -> 4 | J16: ='KD1'!G13 -> 5 | K16: ='DG1'!G13 -> 5 | L16: ='SG1'!G13 -> 3 | M16: ='CM1'!G13 -> 5 | N16: ='VS1'!G13 -> 5 | O16: ='CD1'!G13 -> 4
A17: Growing degree days | B17: Beck et al. 2022 | C17: This measure the accumulated heat above certain base temperature which can estimate the growth and development of plants and insects | D17: 1979-2025 | E17: 6 arcminute | F17: Beck, H.E. et al. (2022) ‘MSWX: Global 3-Hourly 0.1° Bias-Corrected Meteorological Data Including Near-Real-Time Updates and Forecast Ensembles’. Available at: https://doi.org/10.1175/BAMS-D-21-0145.1. | G17: =AVERAGE(I17:O17) -> 4.4285714 | H17: =MEDIAN(I17:O17) -> 4 | I17: ='XH1'!G14 -> 5 | J17: ='KD1'!G14 -> 5 | K17: ='DG1'!G14 -> 4 | L17: ='SG1'!G14 -> 4 | M17: ='CM1'!G14 -> 5 | N17: ='VS1'!G14 -> 4 | O17: ='CD1'!G14 -> 4
A18: Drought index (SPEI)* | B18: Solomon et al. 2023 | C18: Drought index (SPEI) was calculated from two precipitation and two evapotranspiration datasets | D18: 1981-2022 | E18: 5km gridded ~2.5 arcminute | F18: Gebrechorkos, S. H., Peng, J., Dyer, E., Miralles, D. G., Vicente-Serrano, S. M., Funk, C., Beck, H. E., Asfaw, D. T., Singer, M. B., and Dadson, S. J.: Global high-resolution drought indices for 1981–2022, Earth Syst. Sci. Data, 15, 5449–5466, https://doi.org/10.5194/essd-15-5449-2023 | G18: =AVERAGE(I18:O18) -> 3.4285714 | H18: =MEDIAN(I18:O18) -> 3 | I18: ='XH1'!G15 -> 4 | J18: ='KD1'!G15 -> 3 | K18: ='DG1'!G15 -> 4 | L18: ='SG1'!G15 -> 3 | M18: ='CM1'!G15 -> 3 | N18: ='VS1'!G15 -> 3 | O18: ='CD1'!G15 -> 4
A19: Warm spell duration index (WSDI) | B19: Beck et al. 2022 | C19: This indicator shows the amount of conscutive days that the temperature is high (drought). | D19: 1979-2025 | E19: 6 arcminute | F19: Beck, H.E. et al. (2022) ‘MSWX: Global 3-Hourly 0.1° Bias-Corrected Meteorological Data Including Near-Real-Time Updates and Forecast Ensembles’. Available at: https://doi.org/10.1175/BAMS-D-21-0145.1. | G19: =AVERAGE(I19:O19) -> 2.7142857 | H19: =MEDIAN(I19:O19) -> 3 | I19: ='XH1'!G16 -> 4 | J19: ='KD1'!G16 -> 2 | K19: ='DG1'!G16 -> 4 | L19: ='SG1'!G16 -> 1 | M19: ='CM1'!G16 -> 3 | N19: ='VS1'!G16 -> 2 | O19: ='CD1'!G16 -> 3
A20: Harvested crop products (HANPPharv) | B20: Matej et al. 2025 | C20: Shows the amount of mass of carbon being harvested from 22 crop classes | D20: 1992-2020 | E20: 0.5 arcminute | F20: Matej, S., Weidinger, F., Kaufmann, L. et al. A global land-use data cube 1992–2020 based on the Human Appropriation of Net Primary Production. Sci Data 12, 511 (2025). https://doi.org/10.1038/s41597-025-04788-1 | G20: =AVERAGE(I20:O20) -> 3.5714286 | H20: =MEDIAN(I20:O20) -> 4 | I20: ='XH1'!G22 -> 5 | J20: ='KD1'!G22 -> 2 | K20: ='DG1'!G22 -> 4 | L20: ='SG1'!G22 -> 5 | M20: ='CM1'!G22 -> 1 | N20: ='VS1'!G22 -> 4 | O20: ='CD1'!G22 -> 4
A21: Potential Net primary production (NPP Pot) | B21: Matej et al. 2025 | C21: Potential biomass that is available in each area from agriculture and forestry. | D21: 1992-2020 | E21: 0.5 arcminute | F21: Matej, S., Weidinger, F., Kaufmann, L. et al. A global land-use data cube 1992–2020 based on the Human Appropriation of Net Primary Production. Sci Data 12, 511 (2025). https://doi.org/10.1038/s41597-025-04788-1 | G21: =AVERAGE(I21:O21) -> 3.3333333 | H21: =MEDIAN(I21:O21) -> 3.5 | I21: ='XH1'!G23 -> 4 | J21: ='KD1'!G23 -> 3 | K21: ='DG1'!G23 -> 3 | L21: ='SG1'!G23 -> x | M21: ='CM1'!G23 -> 1 | N21: ='VS1'!G23 -> 5 | O21: ='CD1'!G23 -> 4
A22: Evapotranspiration* | B22: Zhang et al. 2024 | C22: This shows the amount of evapotranspiration in the area | D22: 1982-2020 | E22: 6 arcminutes | F22: Zhang, K., Chen, H., Ma, N. et al. A global dataset of terrestrial evapotranspiration and soil moisture dynamics from 1982 to 2020. Sci Data 11, 445 (2024). https://doi.org/10.1038/s41597-024-03271-7 | G22: =AVERAGE(I22:O22) -> 4.4285714 | H22: =MEDIAN(I22:O22) -> 5 | I22: ='XH1'!G8 -> 5 | J22: ='KD1'!G8 -> 5 | K22: ='DG1'!G8 -> 3 | L22: ='SG1'!G8 -> 5 | M22: ='CM1'!G8 -> 5 | N22: ='VS1'!G8 -> 4 | O22: ='CD1'!G8 -> 4
A23: Add -> Frost days | B23: Beck et al. 2022 | C23: Number of days with temperature below 0 celsius | D23: 1979-2025 | E23: 6 arcminute | F23: Beck, H.E. et al. (2022) ‘MSWX: Global 3-Hourly 0.1° Bias-Corrected Meteorological Data Including Near-Real-Time Updates and Forecast Ensembles’. Available at: https://doi.org/10.1175/BAMS-D-21-0145.1.
A24: Add -> Potential Evaporation/Evapotranspiration* (GLEAM) | B24: Miralles, D.G., Bonte, O., Koppa, A. et al. 2025 | C24: Amount of evaporation in each grid | D24: 1980-2023 | E24: 6 arcminutes | F24: https://doi.org/10.1038/s41597-025-04610-y
A25: Add -> Precipitation (wettest 3 consecutive months) (MSWEP/MSWX) | B25: Beck et al. 2022 | C25: The combination of three consecutive monthly precipitation data which has the highest precipitation total value | D25: 1979-2025 | E25: 6 arcminute | F25: Beck, H.E. et al. (2022) ‘MSWX: Global 3-Hourly 0.1° Bias-Corrected Meteorological Data Including Near-Real-Time Updates and Forecast Ensembles’. Available at: https://doi.org/10.1175/BAMS-D-21-0145.1.
A26: Add -> Frequency of droughts during growing season (MSWX) | B26: Beck et al. 2022 | C26: Calculate from monthly drought index and overlay with the growing season days of each year | D26: 1979-2025 | E26: 6 arcminute | F26: Beck, H.E. et al. (2022) ‘MSWX: Global 3-Hourly 0.1° Bias-Corrected Meteorological Data Including Near-Real-Time Updates and Forecast Ensembles’. Available at: https://doi.org/10.1175/BAMS-D-21-0145.1.
A27: Add -> Frequency of dry spells during growing season (MSWX) | B27: Beck et al. 2022 | C27: The number consecutive 5-7 days of little or no rainfall and compared this growing season for each year | D27: 1979-2025 | E27: 6 arcminute | F27: Beck, H.E. et al. (2022) ‘MSWX: Global 3-Hourly 0.1° Bias-Corrected Meteorological Data Including Near-Real-Time Updates and Forecast Ensembles’. Available at: https://doi.org/10.1175/BAMS-D-21-0145.1.
A28: *Note: Might only choose one variable out of these four
A30: Combined System (integrated)
A31: Crop-field Subsystem | C31: Crop-field system is currently considered to be between the two main systems (Physical and Human). This system focuses on the variables that are related to crop species | D31: - | E31: - | I31: ='XH1'!G18 -> - | J31: ='KD1'!G18 -> 0 | K31: ='DG1'!G18 -> - | L31: ='SG1'!G18 -> - | M31: ='CM1'!G18 -> - | N31: ='VS1'!G18 -> -
A32: Diversity of crops (potential of crops that can be grown) | B32: Sara Heikonen / Heikonen et al. 2025 | C32: Diversity of crops (30 major food crop types based on SPAM crops) | D32: 1990-2020 | E32: 5 arcminute | F32: https://mapspam.info/data/ | G32: =AVERAGE(I32:O32) -> 3.4285714 | H32: =MEDIAN(I32:O32) -> 3 | I32: ='XH1'!G19 -> 5 | J32: ='KD1'!G19 -> 5 | K32: ='DG1'!G19 -> 3 | L32: ='SG1'!G19 -> 4 | M32: ='CM1'!G19 -> 2 | N32: ='VS1'!G19 -> 3 | O32: ='CD1'!G19 -> 2
A33: Fraction of cropland per total land area | B33: Matej et al. 2025 | C33: This variable captures the intensity of the cropland in each area by calculating the fraction of actual cropland in the cropland area | D33: 1992-2020 | E33: 0.5 arcminute | F33: https://doi.org/10.1038/s41597-025-04788-1 | G33: =AVERAGE(I33:O33) -> 3 | H33: =MEDIAN(I33:O33) -> 3 | I33: ='XH1'!G20 -> 4 | J33: ='KD1'!G20 -> 5 | K33: ='DG1'!G20 -> 2 | L33: ='SG1'!G20 -> 4 | M33: ='CM1'!G20 -> 1 | N33: ='VS1'!G20 -> 2 | O33: ='CD1'!G20 -> 3
A34: Kilo-calories produced from crops (from SPAM) | B34: SPAM 2000, SPAM 2005, SPAM 2010, SPAM 2020 | C34: Shows the amount of kilo-calories being produced from SPAM crops classes | D34: 2000-2020 | E34: 5 arcminute | F34: https://mapspam.info/data/ | G34: =AVERAGE(I34:O34) -> 3.1428571 | H34: =MEDIAN(I34:O34) -> 3 | I34: ='XH1'!G21 -> 5 | J34: ='KD1'!G21 -> 2 | K34: ='DG1'!G21 -> 4 | L34: ='SG1'!G21 -> 4 | M34: ='CM1'!G21 -> 1 | N34: ='VS1'!G21 -> 3 | O34: ='CD1'!G21 -> 3
A35: Greenhouse gas emissions from cropland | B35: Cao et al. 2025 (Preprint) | C35: Emission of carbon dioxide, methane, and nitrous oxide from 46 crops circa 2020 | D35: 2020 | E35: 5 arcminute | F35: https://doi.org/10.21203/rs.3.rs-6622054/v1 | G35: =AVERAGE(I35:O35) -> 3.0714286 | H35: =MEDIAN(I35:O35) -> 3 | I35: 2.5 | J35: ='KD1'!G24 -> 5 | K35: ='DG1'!G24 -> 4 | L35: ='SG1'!G24 -> 3 | M35: ='CM1'!G24 -> 1 | N35: ='VS1'!G24 -> 2 | O35: ='CD1'!G24 -> 4
A36: Add -> Blue and Green crop water requirement (WATNEEDS) | B36: Chiarelli, D.D., Passera, C., Rosa, L. et al. | C36: Amount of green water (ET) and blue water (irrigation) required for crops | D36: 2000, 2016 | E36: 5 arcminute | F36: https://doi.org/10.1038/s41597-020-00612-0
A37: Add -> Dominant crops | B37: Jackson, Nicole D., et al. 2019 | C37: The most common crop being grown in each grid | D37: 1961-2014 | E37: 30 arcminute | F37: https://doi.org/10.1088/1748-9326/ab3b93
A38: Add -> Ratio of Grazing land and Crop land (create) | B38: Parente et al. 2024 / Matej et al. 2025 | C38: Ratio of amont of grazing land over cropland per grid area | D38: 2000-2022 | E38: 5 arcminute | F38: https://doi.org/10.1038/s41597-024-04139-6 / https://doi.org/10.1038/s41597-025-04788-1
A39: Add -> Trees on cropland (MODIS) | B39: DiMiceli et al. 2022 | C39: Ratio of trees or non-trees on croplands | D39: 2000-2024 | E39: 250 m cellsize ~0.25 arcminute | F39: https://doi.org/10.5067/MODIS/MOD44B.061
A40: Water Subsystem (Water management?)
A42: HUMAN SYSTEM | C42: Human system includes the effect from human towards the crop production system including practices that human has used to influence the crop production as well as the socio-economic variables that affect agriculture workers or policies | D42: - | E42: - | I42: ='XH1'!G27 -> - | J42: ='KD1'!G27 -> 0 | K42: ='DG1'!G27 -> - | L42: ='SG1'!G27 -> - | M42: ='CM1'!G27 -> - | N42: ='VS1'!G27 -> -
A43: Socio-economic Subsytem | C43: This subsystem consisted of socio-economic variables | D43: - | E43: - | I43: ='XH1'!G37 -> - | J43: ='KD1'!G37 -> 0 | K43: ='DG1'!G37 -> - | L43: ='SG1'!G37 -> - | M43: ='CM1'!G37 -> - | N43: ='VS1'!G37 -> -
A44: GNI | B44: Matti Kummu | C44: Gross National Income shows the values of national income for each country | D44: 1990-2021 | E44: admin 2 (country) | G44: =AVERAGE(I44:O44) -> 2.6666667 | H44: =MEDIAN(I44:O44) -> 3 | I44: ='XH1'!G38 -> 3 | J44: ='KD1'!G38 -> 3 | K44: ='DG1'!G38 -> 4 | L44: ='SG1'!G38 -> 3 | M44: ='CM1'!G38 -> 1 | N44: ='VS1'!G38 -> 2 | O44: x
...

Sheet XH1
A1: VARIABLES | B1: REFERENCE | C1: DESCRIPTION | D1: TIMESCALE | E1: RESOLUTION | F1: DOI | G1: SCORING (1-5, 5 being the most important) | I1: Addtional comments/variables?
A3: PHYSICAL SYSTEM | C3: This system includes variables regarding the physical properties of the environment in the area that is not being influenced by human actions | D3: - | E3: - | G3: -
A4: Soil Subsystem | C4: This sub system concentrate on variables that are related to the soil | D4: - | E4: - | G4: -
A5: Soil organic carbon (SOC) | B5: Poggio et al. 2021 | C5: SOC shows the amount of soil organic carbon in each area from 0-60cm of depths | D5: 1960-2020 (mean) | E5: 250 m cellsize ~0.25 arcminute | F5: https://files.isric.org/soilgrids/latest/ | G5: 4
A6: Clay-silt content | B6: Poggio et al. 2021 | C6: Clay-silt shows the combined amount of clay and silt in the soil from 0-60cm depths | D6: 1960-2020 (mean) | E6: 250 m cellsize ~0.25 arcminute | F6: https://files.isric.org/soilgrids/latest/ | G6: 3
A7: Soil plant available phosphorous | B7: McDowell et al. 2023 | C7: Amount of phosphorous that is available for plant to absorb from the soil from 0-20cm depth | D7: 2000-2019 (mean) | E7: 0.5 arcminute | F7: https://figshare.com/articles/dataset/Global_Available_Soil_Phosphorus_Database/14241854 | G7: 4
A8: Evapotranspiration | B8: Zhang et al. 2024 | C8: This shows the amount of evapotranspiration in the area | D8: 1982-2020 | E8: 6 arcminutes | F8: Zhang, K., Chen, H., Ma, N. et al. A global dataset of terrestrial evapotranspiration and soil moisture dynamics from 1982 to 2020. Sci Data 11, 445 (2024). https://doi.org/10.1038/s41597-024-03271-7 | G8: 5
A9: Soil Moisture | B9: Zhang et al. 2024 | C9: Amount of soil moisture throughout the layers along the vertical root distribution | D9: 1982-2020 | E9: 6 arcminutes | F9: Zhang, K., Chen, H., Ma, N. et al. A global dataset of terrestrial evapotranspiration and soil moisture dynamics from 1982 to 2020. Sci Data 11, 445 (2024). https://doi.org/10.1038/s41597-024-03271-7 | G9: 5
A10: Other variables? | G10: x | H10: soil pH?
A11: Climate Subsystem | C11: This subsystem focus on the climatic variables | D11: - | E11: - | G11: -
A12: Aridity index | B12: Lu et al. 2025 | C12: Aridity index is used to determine the aridity in the area by looking at, for example, precipitation or evapotranspiration values | D12: 2003-2022 | E12: 3 arcminute | F12: Lu, J., Yao, L., Qin, J., Jiang, H., & Zhou, C. (2025). Global reconstruction of gridded aridity index and its spatial and temporal characterization from 2003 to 2022. International Journal of Digital Earth, 18(1). https://doi.org/10.1080/17538947.2025.2473639 | G12: 5
A13: Precipitation (MSWEP) | B13: Beck et al. 2019 | C13: MSWEP shows the 3 hourly precipitation data from 1979 to 2017 | D13: 1979-2017 (annual mean) | E13: 6 arcminute | F13: Beck, H. E., E. F. Wood, M. Pan, C. K. Fisher, D. G. Miralles, A. I. J. M. van Dijk, T. R. McVicar, and R. F. Adler, 2019: MSWEP V2 Global 3-Hourly 0.1° Precipitation: Methodology and Quantitative Assessment. Bull. Amer. Meteor. Soc., 100, 473–500, https://doi.org/10.1175/BAMS-D-17-0138.1 | G13: 4
A14: Growing degree days | B14: Beck et al. 2022 | C14: This measure the accumulated heat above certain base temperature which can estimate the growth and development of plants and insects | D14: 1979-2025 | E14: 6 arcminute | F14: Beck, H.E. et al. (2022) ‘MSWX: Global 3-Hourly 0.1° Bias-Corrected Meteorological Data Including Near-Real-Time Updates and Forecast Ensembles’. Available at: https://doi.org/10.1175/BAMS-D-21-0145.1. | G14: 5
A15: Drought index (SPEI) | B15: Solomon et al. 2023 | C15: Drought index (SPEI) was calculated from two precipitation and two evapotranspiration datasets | D15: 1981-2022 | E15: 5km gridded ~2.5 arcminute | F15: Gebrechorkos, S. H., Peng, J., Dyer, E., Miralles, D. G., Vicente-Serrano, S. M., Funk, C., Beck, H. E., Asfaw, D. T., Singer, M. B., and Dadson, S. J.: Global high-resolution drought indices for 1981–2022, Earth Syst. Sci. Data, 15, 5449–5466, https://doi.org/10.5194/essd-15-5449-2023 | G15: 4
A16: Warm spell duration index (WSDI) | B16: Beck et al. 2022 | C16: This indicator shows the amount of conscutive days that the temperature is high (drought). | D16: 1979-2025 | E16: 6 arcminute | F16: Beck, H.E. et al. (2022) ‘MSWX: Global 3-Hourly 0.1° Bias-Corrected Meteorological Data Including Near-Real-Time Updates and Forecast Ensembles’. Available at: https://doi.org/10.1175/BAMS-D-21-0145.1. | G16: 4
A17: Other variables? | G17: x | H17: frost days?
A18: Crop-field Subsystem | C18: Crop-field system is currently considered to be between the two main systems (Physical and Human). This system focuses on the variables that are related to crop species | D18: - | E18: - | G18: -
A19: Diversity of crops | B19: Sara Heikonen / Heikonen et al. 2025 | C19: Diversity of crops (30 major food crop types based on SPAM crops) | D19: 1990-2020 | E19: 5 arcminute | F19: https://mapspam.info/data/ | G19: 5
A20: Fraction of cropland per total land area | B20: Matej et al. 2025 | C20: This variable captures the intensity of the cropland in each area by calculating the fraction of actual cropland in the cropland area | D20: 1992-2020 | E20: 0.5 arcminute | F20: https://mapspam.info/data/ | G20: 4
A21: Kilo-calories produced from crops (from SPAM) | B21: SPAM 2000, SPAM 2005, SPAM 2010, SPAM 2020 | C21: Shows the amount of kilo-calories being produced from SPAM crops classes | D21: 2000-2020 | E21: 5 arcminute | F21: https://mapspam.info/data/ | G21: 5
A22: Harvested crop products (HANPP) | B22: Matej et al. 2025 | C22: Shows the amount of mass of carbon being harvested from 22 crop classes | D22: 1992-2020 | E22: 0.5 arcminute | F22: Matej, S., Weidinger, F., Kaufmann, L. et al. A global land-use data cube 1992–2020 based on the Human Appropriation of Net Primary Production. Sci Data 12, 511 (2025). https://doi.org/10.1038/s41597-025-04788-1 | G22: 5
A23: Potential Net primary production (NPP Pot) | B23: Matej et al. 2025 | C23: Potential biomass that is available in each area from agriculture and forestry. | D23: 1992-2020 | E23: 0.5 arcminute | F23: Matej, S., Weidinger, F., Kaufmann, L. et al. A global land-use data cube 1992–2020 based on the Human Appropriation of Net Primary Production. Sci Data 12, 511 (2025). https://doi.org/10.1038/s41597-025-04788-1 | G23: 4
A24: Greenhouse gas emissions from cropland | B24: Cao et al. 2025 (Preprint) | C24: Emission of carbon dioxide, methane, and nitrous oxide from 46 crops circa 2020 | D24: 2020 | E24: 5 arcminute | F24: https://doi.org/10.21203/rs.3.rs-6622054/v1 | G24: 2/3 | H24: importance may depend on the framing a little bit
A25: Other variables?
G26: -
A27: HUMAN SYSTEM | C27: Human system includes the effect from human towards the crop production system including practices that human has used to influence the crop production as well as the socio-economic variables that affect agriculture workers or policies | D27: - | E27: - | G27: -
A28: Management Subsystem | C28: This subsystem includes variables that is related to management | D28: - | E28: - | G28: -
A29: Field size | B29: Lesiv et al. 2019 | C29: Field size shows the categorial data of field size from 1-5 | D29: 2017 | E29: ~0.3 arcminute | F29: https://pure.iiasa.ac.at/id/eprint/15526/ | G29: 4
A30: Pesticide application rate | B30: Maggi et al. 2019 | C30: Application rate of pesticide per each crop | D30: 2015-2025 | E30: 5 arcminute | F30: https://figshare.com/articles/dataset/PEST-CHEMGRIDS_v1/7764014/5 | G30: 3
A31: N fertilizer application rate | B31: Adalibieke et al. 2023 | C31: This shows the N fertilizer application rate for each crop | D31: 1961-2020 | E31: 5 arcminute | F31: https://data.tpdc.ac.cn/en/data/1e31ad1f-5904-4b49-8796-b379c37e7dba | G31: 5
A32: Fraction of irrigated cropland | B32: Kebede et al. 2025 | C32: Fraction of irrigated cropland with the total cropland area in each grid | D32: 2000-2015 | E32: 5 arcminute | F32: https://doi.org/10.1038/s41597-024-04313-w | G32: 5
A33: Machinery | B33: USDA 2023 | C33: Amount of machinery used in 1000 horsepower (CV) in metric unit per 100 hectares of cropland in each country | D33: 1961-2020 | E33: Country | F33: October 2024 update has remove the data | G33: 4
A34: Agricultural workers | B34: FAO 2023 | C34: Number of agricultural workers in each country | D34: 1991-2020 | E34: Country | F34: https://www.fao.org/faostat/en/#data/OEA | G34: 4
A35: Human pressure (NPP Act / NPP Pot) | B35: Matej et al. 2025 | C35: This shows the human influence on the biomass in Net Primary Production (NPP) in the ecosystem through land use by dividing NPP actual with NPP potential | D35: 1992-2020 | E35: 0.5 arcminute | F35: Matej, S., Weidinger, F., Kaufmann, L. et al. A global land-use data cube 1992–2020 based on the Human Appropriation of Net Primary Production. Sci Data 12, 511 (2025). https://doi.org/10.1038/s41597-025-04788-1 | G35: 4
A36: Other variables? | G36: x | H36: Surface vs groundwater sourced irrigation water? this is available in GMIA
A37: Socio-economic Subsytem | C37: This subsystem consisted of socio-economic variables | D37: - | E37: - | G37: -
A38: GNI | B38: Matti Kummu | C38: Gross National Income shows the values of national income for each country | D38: 1990-2021 | E38: admin 2 | G38: 3
A39: Years of schooling | B39: Matti Kummu | C39: This shows the amount of average years of schooling in the population | D39: 1990-2021 | E39: admin 1 | G39: 3 | H39: all 3 as somewhat proxy datasets
A40: Governance index | B40: Matti Kummu | C40: Governance inis based on World Bank Group (Worldwide Governance Indicators) which shows how good is the governance | D40: 1990-2021 | E40: admin 0 | G40: 3
A41: Other variables? | G41: x

Sheet KD1
A1: VARIABLES | B1: REFERENCE | C1: DESCRIPTION | D1: TIMESCALE | E1: RESOLUTION | F1: DOI | G1: SCORING (1-5, 5 being the most important) | I1: Addtional comments/variables?
A3: PHYSICAL SYSTEM | C3: This system includes variables regarding the physical properties of the environment in the area that is not being influenced by human actions | D3: - | E3: -
A4: Soil Subsystem | C4: This sub system concentrate on variables that are related to the soil | D4: - | E4: -
A5: Soil organic carbon (SOC) | B5: Poggio et al. 2021 | C5: SOC shows the amount of soil organic carbon in each area from 0-60cm of depths | D5: 1960-2020 (mean) | E5: 250 m cellsize ~0.25 arcminute | F5: https://files.isric.org/soilgrids/latest/ | G5: 5
A6: Clay-silt content | B6: Poggio et al. 2021 | C6: Clay-silt shows the combined amount of clay and silt in the soil from 0-60cm depths | D6: 1960-2020 (mean) | E6: 250 m cellsize ~0.25 arcminute | F6: https://files.isric.org/soilgrids/latest/ | G6: 3
A7: Soil plant available phosphorous | B7: McDowell et al. 2023 | C7: Amount of phosphorous that is available for plant to absorb from the soil from 0-20cm depth | D7: 2000-2019 (mean) | E7: 0.5 arcminute | F7: https://figshare.com/articles/dataset/Global_Available_Soil_Phosphorus_Database/14241854 | G7: 3
A8: Evapotranspiration | B8: Zhang et al. 2024 | C8: This shows the amount of evapotranspiration in the area | D8: 1982-2020 | E8: 6 arcminutes | F8: Zhang, K., Chen, H., Ma, N. et al. A global dataset of terrestrial evapotranspiration and soil moisture dynamics from 1982 to 2020. Sci Data 11, 445 (2024). https://doi.org/10.1038/s41597-024-03271-7 | G8: 5
A9: Soil Moisture | B9: Zhang et al. 2024 | C9: Amount of soil moisture throughout the layers along the vertical root distribution | D9: 1982-2020 | E9: 6 arcminutes | F9: Zhang, K., Chen, H., Ma, N. et al. A global dataset of terrestrial evapotranspiration and soil moisture dynamics from 1982 to 2020. Sci Data 11, 445 (2024). https://doi.org/10.1038/s41597-024-03271-7 | G9: 5
A10: Other variables?
A11: Climate Subsystem | C11: This subsystem focus on the climatic variables | D11: - | E11: -
A12: Aridity index | B12: Lu et al. 2025 | C12: Aridity index is used to determine the aridity in the area by looking at, for example, precipitation or evapotranspiration values | D12: 2003-2022 | E12: 3 arcminute | F12: Lu, J., Yao, L., Qin, J., Jiang, H., & Zhou, C. (2025). Global reconstruction of gridded aridity index and its spatial and temporal characterization from 2003 to 2022. International Journal of Digital Earth, 18(1). https://doi.org/10.1080/17538947.2025.2473639 | G12: 5
A13: Precipitation (MSWEP) | B13: Beck et al. 2019 | C13: MSWEP shows the 3 hourly precipitation data from 1979 to 2017 | D13: 1979-2017 (annual mean) | E13: 6 arcminute | F13: Beck, H. E., E. F. Wood, M. Pan, C. K. Fisher, D. G. Miralles, A. I. J. M. van Dijk, T. R. McVicar, and R. F. Adler, 2019: MSWEP V2 Global 3-Hourly 0.1° Precipitation: Methodology and Quantitative Assessment. Bull. Amer. Meteor. Soc., 100, 473–500, https://doi.org/10.1175/BAMS-D-17-0138.1 | G13: 5
A14: Growing degree days | B14: Beck et al. 2022 | C14: This measure the accumulated heat above certain base temperature which can estimate the growth and development of plants and insects | D14: 1979-2025 | E14: 6 arcminute | F14: Beck, H.E. et al. (2022) ‘MSWX: Global 3-Hourly 0.1° Bias-Corrected Meteorological Data Including Near-Real-Time Updates and Forecast Ensembles’. Available at: https://doi.org/10.1175/BAMS-D-21-0145.1. | G14: 5
A15: Drought index (SPEI) | B15: Solomon et al. 2023 | C15: Drought index (SPEI) was calculated from two precipitation and two evapotranspiration datasets | D15: 1981-2022 | E15: 5km gridded ~2.5 arcminute | F15: Gebrechorkos, S. H., Peng, J., Dyer, E., Miralles, D. G., Vicente-Serrano, S. M., Funk, C., Beck, H. E., Asfaw, D. T., Singer, M. B., and Dadson, S. J.: Global high-resolution drought indices for 1981–2022, Earth Syst. Sci. Data, 15, 5449–5466, https://doi.org/10.5194/essd-15-5449-2023 | G15: 3
A16: Warm spell duration index (WSDI) | B16: Beck et al. 2022 | C16: This indicator shows the amount of conscutive days that the temperature is high (drought). | D16: 1979-2025 | E16: 6 arcminute | F16: Beck, H.E. et al. (2022) ‘MSWX: Global 3-Hourly 0.1° Bias-Corrected Meteorological Data Including Near-Real-Time Updates and Forecast Ensembles’. Available at: https://doi.org/10.1175/BAMS-D-21-0145.1. | G16: 2
A17: Other variables? | G17: Renewable water availability
A18: Crop-field Subsystem | C18: Crop-field system is currently considered to be between the two main systems (Physical and Human). This system focuses on the variables that are related to crop species | D18: - | E18: -
A19: Diversity of crops | B19: Sara Heikonen / Heikonen et al. 2025 | C19: Diversity of crops (30 major food crop types based on SPAM crops) | D19: 1990-2020 | E19: 5 arcminute | F19: https://mapspam.info/data/ | G19: 5
A20: Fraction of cropland per total land area | B20: Matej et al. 2025 | C20: This variable captures the intensity of the cropland in each area by calculating the fraction of actual cropland in the cropland area | D20: 1992-2020 | E20: 0.5 arcminute | F20: https://mapspam.info/data/ | G20: 5
A21: Kilo-calories produced from crops (from SPAM) | B21: SPAM 2000, SPAM 2005, SPAM 2010, SPAM 2020 | C21: Shows the amount of kilo-calories being produced from SPAM crops classes | D21: 2000-2020 | E21: 5 arcminute | F21: https://mapspam.info/data/ | G21: 2
A22: Harvested crop products (HANPP) | B22: Matej et al. 2025 | C22: Shows the amount of mass of carbon being harvested from 22 crop classes | D22: 1992-2020 | E22: 0.5 arcminute | F22: Matej, S., Weidinger, F., Kaufmann, L. et al. A global land-use data cube 1992–2020 based on the Human Appropriation of Net Primary Production. Sci Data 12, 511 (2025). https://doi.org/10.1038/s41597-025-04788-1 | G22: 2
A23: Potential Net primary production (NPP Pot) | B23: Matej et al. 2025 | C23: Potential biomass that is available in each area from agriculture and forestry. | D23: 1992-2020 | E23: 0.5 arcminute | F23: Matej, S., Weidinger, F., Kaufmann, L. et al. A global land-use data cube 1992–2020 based on the Human Appropriation of Net Primary Production. Sci Data 12, 511 (2025). https://doi.org/10.1038/s41597-025-04788-1 | G23: 3
A24: Greenhouse gas emissions from cropland | B24: Cao et al. 2025 (Preprint) | C24: Emission of carbon dioxide, methane, and nitrous oxide from 46 crops circa 2020 | D24: 2020 | E24: 5 arcminute | F24: https://doi.org/10.21203/rs.3.rs-6622054/v1 | G24: 5
A25: Other variables? | G25: Crop-specific yield (irrig./rainfed); crop-specific harvested area (irrig./rainfed)
A27: HUMAN SYSTEM | C27: Human system includes the effect from human towards the crop production system including practices that human has used to influence the crop production as well as the socio-economic variables that affect agriculture workers or policies | D27: - | E27: -
A28: Management Subsystem | C28: This subsystem includes variables that is related to management | D28: - | E28: -
A29: Field size | B29: Lesiv et al. 2019 | C29: Field size shows the categorial data of field size from 1-5 | D29: 2017 | E29: ~0.3 arcminute | F29: https://pure.iiasa.ac.at/id/eprint/15526/ | G29: 4
A30: Pesticide application rate | B30: Maggi et al. 2019 | C30: Application rate of pesticide per each crop | D30: 2015-2025 | E30: 5 arcminute | F30: https://figshare.com/articles/dataset/PEST-CHEMGRIDS_v1/7764014/5 | G30: 4
A31: N fertilizer application rate | B31: Adalibieke et al. 2023 | C31: This shows the N fertilizer application rate for each crop | D31: 1961-2020 | E31: 5 arcminute | F31: https://data.tpdc.ac.cn/en/data/1e31ad1f-5904-4b49-8796-b379c37e7dba | G31: 5
A32: Fraction of irrigated cropland | B32: Kebede et al. 2025 | C32: Fraction of irrigated cropland with the total cropland area in each grid | D32: 2000-2015 | E32: 5 arcminute | F32: https://doi.org/10.1038/s41597-024-04313-w | G32: 5
A33: Machinery | B33: USDA 2023 | C33: Amount of machinery used in 1000 horsepower (CV) in metric unit per 100 hectares of cropland in each country | D33: 1961-2020 | E33: Country | F33: October 2024 update has remove the data | G33: 5
A34: Agricultural workers | B34: FAO 2023 | C34: Number of agricultural workers in each country | D34: 1991-2020 | E34: Country | F34: https://www.fao.org/faostat/en/#data/OEA | G34: 5
A35: Human pressure (NPP Act / NPP Pot) | B35: Matej et al. 2025 | C35: This shows the human influence on the biomass in Net Primary Production (NPP) in the ecosystem through land use by dividing NPP actual with NPP potential | D35: 1992-2020 | E35: 0.5 arcminute | F35: Matej, S., Weidinger, F., Kaufmann, L. et al. A global land-use data cube 1992–2020 based on the Human Appropriation of Net Primary Production. Sci Data 12, 511 (2025). https://doi.org/10.1038/s41597-025-04788-1 | G35: 3
A36: Other variables? | G36: Blue and green crop water requirements
A37: Socio-economic Subsytem | C37: This subsystem consisted of socio-economic variables | D37: - | E37: -
A38: GNI | B38: Matti Kummu | C38: Gross National Income shows the values of national income for each country | D38: 1990-2021 | E38: admin 2 | G38: 3
A39: Years of schooling | B39: Matti Kummu | C39: This shows the amount of average years of schooling in the population | D39: 1990-2021 | E39: admin 1 | G39: 5
A40: Governance index | B40: Matti Kummu | C40: Governance inis based on World Bank Group (Worldwide Governance Indicators) which shows how good is the governance | D40: 1990-2021 | E40: admin 0 | G40: 3
A41: Other variables?

Sheet DG1
A1: VARIABLES | B1: REFERENCE | C1: DESCRIPTION | D1: TIMESCALE | E1: RESOLUTION | F1: DOI | G1: SCORING (1-5, 5 being the most important) | I1: Addtional comments/variables?
A3: PHYSICAL SYSTEM | C3: This system includes variables regarding the physical properties of the environment in the area that is not being influenced by human actions | D3: - | E3: - | G3: -
A4: Soil Subsystem | C4: This sub system concentrate on variables that are related to the soil | D4: - | E4: - | G4: -
A5: Soil organic carbon (SOC) | B5: Poggio et al. 2021 | C5: SOC shows the amount of soil organic carbon in each area from 0-60cm of depths | D5: 1960-2020 (mean) | E5: 250 m cellsize ~0.25 arcminute | F5: https://files.isric.org/soilgrids/latest/ | G5: 3
A6: Clay-silt content | B6: Poggio et al. 2021 | C6: Clay-silt shows the combined amount of clay and silt in the soil from 0-60cm depths | D6: 1960-2020 (mean) | E6: 250 m cellsize ~0.25 arcminute | F6: https://files.isric.org/soilgrids/latest/ | G6: 2
A7: Soil plant available phosphorous | B7: McDowell et al. 2023 | C7: Amount of phosphorous that is available for plant to absorb from the soil from 0-20cm depth | D7: 2000-2019 (mean) | E7: 0.5 arcminute | F7: https://figshare.com/articles/dataset/Global_Available_Soil_Phosphorus_Database/14241854 | G7: 4
